<?xml version="1.0"?>
<robot xmlns:xacro="http://www.ros.org/wiki/xacro" name="btechbot">


 <link name = "base_link">
 </link>

 <joint name = "chassis_joint" type = "fixed">
   <parent link = "base_link" />
   <child link = "chassis" />
   <origin xyz = "0 0 0" />
 </joint>

 <!--Chassis Link-->

  <link name = "chassis">
    <visual>
      <geometry>
        <box size = "0.22 0.18 0.003"/>
      </geometry>
      <origin xyz = "0 0 0"/>
      <material name = "jute_fibre">
        <color rgba = "0.5 0.25 0.0 1.0"/>
      </material>
    </visual>
    <collision>
      <geometry>
        <box size = "0.22 0.18 0.003"/>
      </geometry>
      <origin xyz = "0 0 0"/>
    </collision>
    <inertial>
      <mass value = "0.05" />
      <origin xyz = "0 0 0" rpy = "0 0 0" />
      <inertia ixx = "0.001953" ixz = "0" ixy="0" iyy = "0.01386" iyz = "0" izz = "0.014456" />
    </inertial>
  </link>
  
  <gazebo reference="chassis">
    <material>Gazebo/Orange</material>
  </gazebo>

  <!-- Left Wheel -->

  <link name = "left_wheel">
    <visual>
      <geometry>
        <cylinder radius = "0.022" length = "0.018" />
      </geometry>
      <material name = "black tire">
        <color rgba = "0.1 0.1 0.1 1.0"/>
      </material>
   </visual>
   <collision>
      <geometry>
        <cylinder radius = "0.022" length = "0.018" />
      </geometry>
   </collision>
   <inertial>
      <mass value = "0.018" />
      <origin xyz = "0 0 0" rpy = "0 0 0" />
      <inertia ixx = "0.0002" ixz = "0" ixy="0" iyy = "0.0002" iyz = "0" izz = "0.00004" />
    </inertial>
  </link>

  <gazebo reference="left_wheel">
    <material>Gazebo/Black</material>
  </gazebo>
  
  <joint name = "lwheel" type="continuous">
    <parent link = "base_link"/>
    <child link = "left_wheel"/>
    <origin xyz = "0 0.099 0" rpy = "1.587 0 0"/>
    <axis xyz = "0 0 -1"/>
  </joint>

 <!-- Right Wheel -->

  <link name = "right_wheel">
    <visual>
      <geometry>
        <cylinder radius = "0.022" length = "0.018" />
      </geometry>
      <material name = "black tire">
        <color rgba = "0.1 0.1 0.1 1.0"/>
      </material>
     </visual>
     <collision>
      <geometry>
        <cylinder radius = "0.022" length = "0.018" />
      </geometry>
     </collision>
     <inertial>
      <mass value = "0.018" />
      <origin xyz = "0 0 0" rpy = "0 0 0" />
      <inertia ixx = "0.0002" ixz = "0" ixy="0" iyy = "0.0002" iyz = "0" izz = "0.00004" />
    </inertial>
   </link>
   
   <gazebo reference="right_wheel">
    <material>Gazebo/Black</material>
  </gazebo>

  <joint name = "rwheel" type="continuous">
    <parent link = "base_link"/>
    <child link = "right_wheel"/>
    <origin xyz = "0 -0.099 0" rpy = "-1.587 0 0"/>
    <axis xyz = "0 0 1"/>
  </joint>

 <!-- Front Caster wheel -->

 <joint name = "fcaster" type = "fixed">
   <parent link = "base_link"/>
   <child link = "front_caster" />
   <origin xyz = "0.0775 0 0" rpy = "0 0 0"/>
   <!--axis xyz = "1 1 1" /-->
 </joint>

 <gazebo reference="front_caster">
   <material>Gazebo/Violet</material>
   <mu1 value="0.001"/>
   <mu2 value="0.001"/>
 </gazebo>

 <link name = "front_caster">
   <visual>
     <geometry>
       <sphere radius = "0.022" />
     </geometry>
     <material name = "grey">
       <color rgba = "0.2 0.2 0.2 1.0" />
     </material>
   </visual>
   <collision>
     <geometry>
       <sphere radius = "0.022" />
     </geometry>
   </collision>
   <inertial>
      <mass value = "0.015" />
      <origin xyz = "0 0 0" rpy = "0 0 0" />
      <inertia ixx = "0.000108" ixy="0" ixz = "0" iyy = "0.000108" iyz = "0" izz = "0.000108" />
    </inertial>
 </link>

 <!-- Back Caster Wheel -->

 <joint name = "bcaster" type = "fixed">
   <parent link = "base_link"/>
   <child link = "back_caster" />
   <origin xyz = "-0.0775 0 0" rpy = "0 0 0"/>
   <!--axis xyz = "1 1 1" /-->
 </joint>

 <link name = "back_caster">
   <visual>
     <geometry>
        <sphere radius = "0.022" />
     </geometry>
     <material name = "grey">
       <color rgba = "0.2 0.2 0.2 1.0" />
     </material>
   </visual>
   <collision>
     <geometry>
        <sphere radius = "0.022" />
     </geometry>
   </collision>
   <inertial>
      <mass value = "0.015" />
      <origin xyz = "0 0 0" rpy = "0 0 0" />
      <inertia ixx = "0.000108" ixy="0" ixz = "0" iyy = "0.000108" iyz = "0" izz = "0.000108" />
    </inertial>
 </link>

  <!-- Joint and links for Columns of 1st floor-->

  <link name = "column1_1">
    <visual>
      <geometry>
        <cylinder radius = "0.0025" length = "0.05"/>
      </geometry>
      <material name = "col">
        <color rgba = "0.5 0.1 0.1 1.0" />
      </material>
   </visual>
   <collision>
      <geometry>
        <cylinder radius = "0.0025" length = "0.05"/>
      </geometry>
   </collision>
   <inertial>
      <mass value = "0.01" />
      <origin xyz = "0 0 0" rpy = "0 0 0" />
      <inertia ixx = "0.000003" ixy="0" ixz = "0" iyy = "0.000050" iyz = "0" izz = "0.000050" />
    </inertial>
 </link>

 <joint name = "column1.1" type = "fixed">
   <parent link = "chassis" />
   <child link = "column1_1" />
   <origin xyz = "0.055 0 0.025" rpy = "0 0 0" />
 </joint>

 <!-- Column1.2 -->

 <joint name = "column1.2" type = "fixed">
   <parent link = "chassis" />
   <child link = "column1_2" />
   <origin xyz = "-0.055 0 0.025" rpy = "0 0 0" />
 </joint>

 <link name = "column1_2">
   <visual>
     <geometry>
       <cylinder radius = "0.0025" length = "0.05"/>
     </geometry>
     <material name = "col">
       <color rgba = "0.5 0.1 0.1 1.0" />
     </material>
   </visual>
   <collision>
     <geometry>
       <cylinder radius = "0.0025" length = "0.05"/>
     </geometry>
   </collision>
   <inertial>
      <mass value = "0.01" />
      <origin xyz = "0 0 0" rpy = "0 0 0" />
      <inertia ixx = "0.000003" ixy="0" ixz = "0" iyy = "0.000050" iyz = "0" izz = "0.000050" />
    </inertial>
 </link>

 <!-- Column1.3 -->

 <joint name = "column1.3" type = "fixed">
   <parent link = "chassis" />
   <child link = "column1_3" />
   <origin xyz = "0 -0.045 0.025" rpy = "0 0 0" />
 </joint>

 <link name = "column1_3">
   <visual>
     <geometry>
       <cylinder radius = "0.0025" length = "0.05"/>
     </geometry>
     <material name = "col">
       <color rgba = "0.5 0.1 0.1 1.0" />
     </material>
   </visual>
   <collision>
     <geometry>
       <cylinder radius = "0.0025" length = "0.05"/>
     </geometry>
   </collision>
   <inertial>
      <mass value = "0.01" />
      <origin xyz = "0 0 0" rpy = "0 0 0" />
      <inertia ixx = "0.000003" ixy="0" ixz = "0" iyy = "0.000050" iyz = "0" izz = "0.000050" />
    </inertial>
 </link>

 <!-- Column1.4 -->

 <joint name = "column1.4" type = "fixed">
   <parent link = "chassis" />
   <child link = "column1_4" />
   <origin xyz = "0 0.045 0.025" rpy = "0 0 0" />
 </joint>

 <link name = "column1_4">
    <visual>
      <geometry>
        <cylinder radius = "0.0025" length = "0.05"/>
      </geometry>
      <material name = "col">   
	 <color rgba = "0.5 0.1 0.1 1.0" />
      </material>
   </visual>
   <collision>
      <geometry>
        <cylinder radius = "0.0025" length = "0.05"/>
      </geometry>
   </collision>
   <inertial>
      <mass value = "0.01" />
      <origin xyz = "0 0 0" rpy = "0 0 0" />
      <inertia ixx = "0.000003" ixy="0" ixz = "0" iyy = "0.000050" iyz = "0" izz = "0.000050" />
    </inertial>
 </link>

 <!-- Floor 1 -->

 <link name = "floor1">
   <visual>
     <geometry>
       <cylinder radius = "0.075" length = "0.003" />
     </geometry>
     <material name = "white">
       <color rgba = "0.8 0.4 0.0 1" />
     </material>
   </visual>
   <collision>
     <geometry>
       <cylinder radius = "0.075" length = "0.003" />
     </geometry>
   </collision>
   <inertial>
      <mass value = "0.04" />
      <origin xyz = "0 0 0" rpy = "0 0 0" />
      <inertia ixx = "0.000625" ixy="0" ixz = "0" iyy = "0.000625" iyz = "0" izz = "0.00008333" />
    </inertial>
 </link> 
 
 <gazebo reference="floor1">
    <material>Gazebo/Red</material>
  </gazebo>
	 
 <!--Column Floor Joints-->

 <joint name = "floor1.1" type = "fixed">
   <parent link = "column1_1" />
   <child link = "floor1" />
   <origin xyz = "-0.055 0 0.025" rpy = "0 0 0" />
 </joint>

 <!--joint name = "floor1.2" type = "fixed">
   <parent link = "column1_2" />
   <child link = "floor1" />
   <origin xyz = "0.055 0 0.025" rpy = "0 0 0" />
 </joint-->

 <!--joint name = "floor1.3" type = "fixed">
   <parent link = "column1_3" />
   <child link = "floor1" />
   <origin xyz = "0 -0.045 0.025" rpy = "0 0 0" />
 </joint-->

 <!--joint name = "floor1.4" type = "fixed">
   <parent link = "column1_4" />
   <child link = "floor1" />
   <origin xyz = "0 -0.045 0.025" rpy = "0 0 0" />
 </joint-->

<!-- Joints and links for Floor 2 Columns -->

 <link name = "column2_1">
   <visual>
     <geometry>
       <cylinder radius = "0.0025" length = "0.05"/>
     </geometry>
     <material name = "col">
        <color rgba = "0.5 0.1 0.1 1.0" />
     </material>
   </visual>
   <collision>
     <geometry>
       <cylinder radius = "0.0025" length = "0.05"/>
     </geometry>
   </collision>
   <inertial>
      <mass value = "0.01" />
      <origin xyz = "0 0 0" rpy = "0 0 0" />
      <inertia ixx = "0.000003" ixy="0" ixz = "0" iyy = "0.000050" iyz = "0" izz = "0.000050" />
    </inertial>
 </link>

 <joint name = "column2.1" type = "fixed">
    <parent link = "floor1" />
    <child link = "column2_1" />
    <origin xyz = "0.055 0 0.025" rpy = "0 0 0" />
 </joint>

 <!-- Column2.2 -->

 <joint name = "column2.2" type = "fixed">
   <parent link = "floor1" />
   <child link = "column2_2" />
   <origin xyz = "-0.055 0 0.025" rpy = "0 0 0" />
 </joint>

 <link name = "column2_2">
   <visual>
     <geometry>
       <cylinder radius = "0.0025" length = "0.05"/>
     </geometry>
     <material name = "col">
       <color rgba = "0.5 0.1 0.1 1.0" />	
     </material>
   </visual>
   <collision>
     <geometry>
       <cylinder radius = "0.0025" length = "0.05"/>
     </geometry>
   </collision>
   <inertial>
      <mass value = "0.01" />
      <origin xyz = "0 0 0" rpy = "0 0 0" />
      <inertia ixx = "0.000003" ixy="0" ixz = "0" iyy = "0.000050" iyz = "0" izz = "0.000050" />
    </inertial>
  </link>

 <!-- Column2.3 -->

 <joint name = "column2.3" type = "fixed">
   <parent link = "floor1" />
   <child link = "column2_3" />
   <origin xyz = "0 -0.045 0.025" rpy = "0 0 0" />
 </joint>

 <link name = "column2_3">
   <visual>
     <geometry>
        <cylinder radius = "0.0025" length = "0.05"/>
     </geometry>
     <material name = "col">
       <color rgba = "0.5 0.1 0.1 1.0" />
     </material>
   </visual>
   <collision>
     <geometry>
        <cylinder radius = "0.0025" length = "0.05"/>
     </geometry>
   </collision>
   <inertial>
      <mass value = "0.01" />
      <origin xyz = "0 0 0" rpy = "0 0 0" />
      <inertia ixx = "0.000003" ixy="0" ixz = "0" iyy = "0.000050" iyz = "0" izz = "0.000050" />
    </inertial>
 </link>

 <!-- Column2.4 -->

 <joint name = "column2.4" type = "fixed">
   <parent link = "floor1" />
   <child link = "column2_4" />
   <origin xyz = "0 0.045 0.025" rpy = "0 0 0" />
 </joint>

 <link name = "column2_4" type = "fixed">
   <visual>
     <geometry>
       <cylinder radius = "0.0025" length = "0.05" />
     </geometry>
     <material name = "col">
       <color rgba = "0.5 0.1 0.1 1.0" />
     </material>
   </visual>
   <collision>
     <geometry>
       <cylinder radius = "0.0025" length = "0.05" />
     </geometry>
   </collision>
   <inertial>
      <mass value = "0.01" />
      <origin xyz = "0 0 0" rpy = "0 0 0" />
      <inertia ixx = "0.000003" ixy="0" ixz = "0" iyy = "0.000050" iyz = "0" izz = "0.000050" />
    </inertial>
 </link> 

 <!-- Floor 2 -->

 <link name = "floor2">
   <visual>
     <geometry>
       <cylinder radius = "0.075" length = "0.003" />
     </geometry>
     <material name = "white">
       <color rgba = "0.8 0.4 0.0 1" />
     </material>
   </visual>
   <collision>
     <geometry>
       <cylinder radius = "0.075" length = "0.003" />
     </geometry>
   </collision>
   <inertial>
      <mass value = "0.04" />
      <origin xyz = "0 0 0" rpy = "0 0 0" />
      <inertia ixx = "0.000625" ixy="0" ixz = "0" iyy = "0.000625" iyz = "0" izz = "0.00008333" />
    </inertial>
 </link>
 
  <gazebo reference="floor2">
    <material>Gazebo/Red</material>
  </gazebo>

 <!--Column Floor Joints-->

 <!--joint name = "floor2.1" type = "fixed">
   <parent link = "column2_1" />
   <child link = "floor2" />
   <origin xyz = "-0.055 0 0.025" rpy = "0 0 0" />
 </joint-->

 <joint name = "floor2.2" type = "fixed">
   <parent link = "column2_2" />
   <child link = "floor2" />
   <origin xyz = "0.055 0 0.025" rpy = "0 0 0" />
 </joint>
 
 <joint name="laser_joint" type="fixed">
  <parent link="floor2"/>
  <child link="laser_frame"/>
  <origin xyz="0 0 0.022" rpy="0 0 0"/>
</joint>

<link name="laser_frame">
  <visual>
      <geometry>
        <cylinder radius = "0.022" length = "0.018" />
      </geometry>
      <material name = "blue">
        <color rgba = "0.1 0.1 1.0 1.0"/>
      </material>
   </visual>
   <collision>
      <geometry>
        <cylinder radius = "0.022" length = "0.018" />
      </geometry>
   </collision>
   <inertial>
      <mass value = "0.018" />
      <origin xyz = "0 0 0" rpy = "0 0 0" />
      <inertia ixx = "0.0002" ixz = "0" ixy="0" iyy = "0.0002" iyz = "0" izz = "0.00004" />
    </inertial>
</link>

 <!--joint name = "floor2.3" type = "fixed">
   <parent link = "column2_3" />
   <child link = "floor2" />
   <origin xyz = "0 -0.045 0.025" rpy = "0 0 0" />
 </joint-->

 <!--joint name = "floor2_4" type = "fixed">
   <parent link = "column2_4" />
   <child link = "floor2" />
   <origin xyz = "0 -0.045 0.025" rpy = "0 0 0" />
 </joint-->
 <!--
 <controller name="joint_state_controller" type="joint_state_controller/JointStateController">
   <joint name="lwheel" hardware_interface="hardware_interface/JointStateInterface" />
   <joint name="rwheel" hardware_interface="hardware_interface/JointStateInterface" />
 </controller>

       <transmission name="left_wheel_transmission">
        <type>transmission_interface/SimpleTransmission</type>
        <joint name="lwheel">
          <hardwareInterface>hardware_interface/VelocityJointInterface</hardwareInterface>
        </joint>
        <actuator name="left_wheel_motor">
          <mechanicalReduction>1</mechanicalReduction>
        </actuator>
      </transmission>

      <transmission name="right_wheel_transmission">
        <type>transmission_interface/SimpleTransmission</type>
        <joint name="rwheel">
          <hardwareInterface>hardware_interface/VelocityJointInterface</hardwareInterface>
        </joint>
        <actuator name="right_wheel_motor">
          <mechanicalReduction>1</mechanicalReduction>
        </actuator>
      </transmission>

 <gazebo>
   <plugin name="gazebo_ros_control" filename="libgazebo_ros_control.so">
	   <robotNamespace>/btechbot</robotNamespace>
	   <controlPeriod>0.001</controlPeriod>
	   <robotSimType>gazebo_ros_control/DefaultRobotHWSim</robotSimType> 
   </plugin>
 </gazebo>
	 -->

<gazebo reference="laser_frame">
	<sensor name="laser" type="ray">
		<pose>0 0 0 0 0 0</pose>
		<visualize>true</visualize>
		<update_rate>10</update_rate>
		<ray>
			<scan>
			<horizontal>
				<samples>360</samples>
				<resolution>1</resolution>
				<min_angle>-3.14</min_angle>
				<max_angle>3.14</max_angle>
			</horizontal>
			</scan>
			<range>
				<min>0.3</min>
				<max>12</max>
				<resolution>0.01</resolution>
			</range>
		</ray>
		<plugin name="laser_contrller" filename="libgazebo_ros_laser.so">
			<ros>
				<argument>=~/out:=scan</argument>
			</ros>
			<topicName>sensor_msgs/LaserScan</topicName>
			<frameName>laser_frame</frameName>
		</plugin>
	</sensor>
</gazebo>

<gazebo>
	<plugin name="diff_drive_btechbot" filename="libgazebo_ros_diff_drive.so">

		<leftJoint>lwheel</leftJoint>
		<rightJoint>rwheel</rightJoint>
		<wheelSeparation>0.18</wheelSeparation>
		<wheelDiameter>0.044</wheelDiameter>
		<commandTopic>cmd_vel</commandTopic>
		<odomTopic>odom</odomTopic>
		<maxTorque>100</maxTorque>
		<maxAcceleration>10.0</maxAcceleration>
		
		<odometryFrame>odom</odometryFrame>
		<robotBaseFrame>base_link</robotBaseFrame>
	        <publishWheelJointState>true</publishWheelJointState>	
		<publishOdom>true</publishOdom>
		<publishOdomTf>true</publishOdomTf>
		<publishWheelTf>true</publishWheelTf>
</plugin>
</gazebo>

</robot>
